Workbook

Sheet 入力画面
C1: Voyage No. | D1: =#REF! -> #REF! | J1: 乗組員名簿 | N1: CREW LIST
C2: Name of Port | D2: =#REF! -> #REF! | E2: Date of Arrival | H2: =#REF! -> #REF! | K2: 到着 | N2: 出発
D3: =#REF! -> #REF! | E3: =#REF! -> #REF! | K3: Arrival | N3: Departure
A4: 1.船舶の名称 | D4: =#REF! -> #REF! | E4: 2.到着港※／出発港※ | H4: 大文字入力 | N4: 3.到着日※／出発日※
A5: Name of ship | E5: Port of arrival/depature | H5: =#REF! -> #REF! | N5: Date of arrival/depature
A6: 4.船舶の国籍 | D6: =#REF! -> #REF! | E6: 5.前寄港地※
A7: Nationality of ship | E7: Port arrived from | J7: yyyy/mm/dd | K7: yyyy/mm/dd
A8: 番号 | B8: 職名 | C8: Rank | D8: 日本書式用氏名 | F8: Family Name | G8: Given Name | H8: Country of Birth | I8: Nationality | J8: 生年月日 | K8: 乗船日及び場所 | N8: 現住所 / 国籍 | O8: PASSPORT NO. | P8: Passport Expiry
A9: 1 | B9: =IF(#REF!="","",#REF!) -> #REF! | C9: =IF(#REF!="","",#REF!) -> #REF! | D9: =IF(#REF!="",G9,#REF!) -> #REF! | E9: =IF(#REF!="",F9,"") -> #REF! | F9: =IF(#REF!="","",#REF!) -> #REF! | G9: =IF(#REF!="","",#REF!) -> #REF! | H9: =IF(#REF!="","",#REF!) -> #REF! | I9: =IF(#REF!="","",#REF!) -> #REF! | J9: =IF(#REF!="","",#REF!) -> #REF! | K9: =IF(#REF!="","",#REF!) -> #REF! | L9: =IF(#REF!="","",#REF!) -> #REF! | M9: =IF(#REF!="","",#REF!) -> #REF! | ... P9: =IF(#REF!="","",#REF!) -> #REF!
A10: 2 | B10: =IF(#REF!="","",#REF!) -> #REF! | C10: =IF(#REF!="","",#REF!) -> #REF! | D10: =IF(#REF!="",G10,#REF!) -> #REF! | E10: =IF(#REF!="",F10,"") -> #REF! | F10: =IF(#REF!="","",#REF!) -> #REF! | G10: =IF(#REF!="","",#REF!) -> #REF! | H10: =IF(#REF!="","",#REF!) -> #REF! | I10: =IF(#REF!="","",#REF!) -> #REF! | J10: =IF(#REF!="","",#REF!) -> #REF! | K10: =IF(#REF!="","",#REF!) -> #REF! | L10: =IF(#REF!="","",#REF!) -> #REF! | M10: =IF(#REF!="","",#REF!) -> #REF! | ... P10: =IF(#REF!="","",#REF!) -> #REF!
A11: 3 | B11: =IF(#REF!="","",#REF!) -> #REF! | C11: =IF(#REF!="","",#REF!) -> #REF! | D11: =IF(#REF!="",G11,#REF!) -> #REF! | E11: =IF(#REF!="",F11,"") -> #REF! | F11: =IF(#REF!="","",#REF!) -> #REF! | G11: =IF(#REF!="","",#REF!) -> #REF! | H11: =IF(#REF!="","",#REF!) -> #REF! | I11: =IF(#REF!="","",#REF!) -> #REF! | J11: =IF(#REF!="","",#REF!) -> #REF! | K11: =IF(#REF!="","",#REF!) -> #REF! | L11: =IF(#REF!="","",#REF!) -> #REF! | M11: =IF(#REF!="","",#REF!) -> #REF! | ... P11: =IF(#REF!="","",#REF!) -> #REF!
A12: 4 | B12: =IF(#REF!="","",#REF!) -> #REF! | C12: =IF(#REF!="","",#REF!) -> #REF! | D12: =IF(#REF!="",G12,#REF!) -> #REF! | E12: =IF(#REF!="",F12,"") -> #REF! | F12: =IF(#REF!="","",#REF!) -> #REF! | G12: =IF(#REF!="","",#REF!) -> #REF! | H12: =IF(#REF!="","",#REF!) -> #REF! | I12: =IF(#REF!="","",#REF!) -> #REF! | J12: =IF(#REF!="","",#REF!) -> #REF! | K12: =IF(#REF!="","",#REF!) -> #REF! | L12: =IF(#REF!="","",#REF!) -> #REF! | M12: =IF(#REF!="","",#REF!) -> #REF! | ... P12: =IF(#REF!="","",#REF!) -> #REF!
A13: 3 | B13: =IF(#REF!="","",#REF!) -> #REF! | C13: =IF(#REF!="","",#REF!) -> #REF! | D13: =IF(#REF!="",G13,#REF!) -> #REF! | E13: =IF(#REF!="",F13,"") -> #REF! | F13: =IF(#REF!="","",#REF!) -> #REF! | G13: =IF(#REF!="","",#REF!) -> #REF! | H13: =IF(#REF!="","",#REF!) -> #REF! | I13: =IF(#REF!="","",#REF!) -> #REF! | J13: =IF(#REF!="","",#REF!) -> #REF! | K13: =IF(#REF!="","",#REF!) -> #REF! | L13: =IF(#REF!="","",#REF!) -> #REF! | M13: =IF(#REF!="","",#REF!) -> #REF! | ... P13: =IF(#REF!="","",#REF!) -> #REF!
A14: 4 | B14: =IF(#REF!="","",#REF!) -> #REF! | C14: =IF(#REF!="","",#REF!) -> #REF! | D14: =IF(#REF!="",G14,#REF!) -> #REF! | E14: =IF(#REF!="",F14,"") -> #REF! | F14: =IF(#REF!="","",#REF!) -> #REF! | G14: =IF(#REF!="","",#REF!) -> #REF! | H14: =IF(#REF!="","",#REF!) -> #REF! | I14: =IF(#REF!="","",#REF!) -> #REF! | J14: =IF(#REF!="","",#REF!) -> #REF! | K14: =IF(#REF!="","",#REF!) -> #REF! | L14: =IF(#REF!="","",#REF!) -> #REF! | M14: =IF(#REF!="","",#REF!) -> #REF! | ... P14: =IF(#REF!="","",#REF!) -> #REF!
A15: 7 | B15: =IF(#REF!="","",#REF!) -> #REF! | C15: =IF(#REF!="","",#REF!) -> #REF! | D15: =IF(#REF!="",G15,#REF!) -> #REF! | E15: =IF(#REF!="",F15,"") -> #REF! | F15: =IF(#REF!="","",#REF!) -> #REF! | G15: =IF(#REF!="","",#REF!) -> #REF! | H15: =IF(#REF!="","",#REF!) -> #REF! | I15: =IF(#REF!="","",#REF!) -> #REF! | J15: =IF(#REF!="","",#REF!) -> #REF! | K15: =IF(#REF!="","",#REF!) -> #REF! | L15: =IF(#REF!="","",#REF!) -> #REF! | M15: =IF(#REF!="","",#REF!) -> #REF! | ... P15: =IF(#REF!="","",#REF!) -> #REF!
A16: 8 | B16: =IF(#REF!="","",#REF!) -> #REF! | C16: =IF(#REF!="","",#REF!) -> #REF! | D16: =IF(#REF!="",G16,#REF!) -> #REF! | E16: =IF(#REF!="",F16,"") -> #REF! | F16: =IF(#REF!="","",#REF!) -> #REF! | G16: =IF(#REF!="","",#REF!) -> #REF! | H16: =IF(#REF!="","",#REF!) -> #REF! | I16: =IF(#REF!="","",#REF!) -> #REF! | J16: =IF(#REF!="","",#REF!) -> #REF! | K16: =IF(#REF!="","",#REF!) -> #REF! | L16: =IF(#REF!="","",#REF!) -> #REF! | M16: =IF(#REF!="","",#REF!) -> #REF! | ... P16: =IF(#REF!="","",#REF!) -> #REF!
A17: 9 | B17: =IF(#REF!="","",#REF!) -> #REF! | C17: =IF(#REF!="","",#REF!) -> #REF! | D17: =IF(#REF!="",G17,#REF!) -> #REF! | E17: =IF(#REF!="",F17,"") -> #REF! | F17: =IF(#REF!="","",#REF!) -> #REF! | G17: =IF(#REF!="","",#REF!) -> #REF! | H17: =IF(#REF!="","",#REF!) -> #REF! | I17: =IF(#REF!="","",#REF!) -> #REF! | J17: =IF(#REF!="","",#REF!) -> #REF! | K17: =IF(#REF!="","",#REF!) -> #REF! | L17: =IF(#REF!="","",#REF!) -> #REF! | M17: =IF(#REF!="","",#REF!) -> #REF! | ... P17: =IF(#REF!="","",#REF!) -> #REF!
A18: 10 | B18: =IF(#REF!="","",#REF!) -> #REF! | C18: =IF(#REF!="","",#REF!) -> #REF! | D18: =IF(#REF!="",G18,#REF!) -> #REF! | E18: =IF(#REF!="",F18,"") -> #REF! | F18: =IF(#REF!="","",#REF!) -> #REF! | G18: =IF(#REF!="","",#REF!) -> #REF! | H18: =IF(#REF!="","",#REF!) -> #REF! | I18: =IF(#REF!="","",#REF!) -> #REF! | J18: =IF(#REF!="","",#REF!) -> #REF! | K18: =IF(#REF!="","",#REF!) -> #REF! | L18: =IF(#REF!="","",#REF!) -> #REF! | M18: =IF(#REF!="","",#REF!) -> #REF! | ... P18: =IF(#REF!="","",#REF!) -> #REF!
A19: 11 | B19: =IF(#REF!="","",#REF!) -> #REF! | C19: =IF(#REF!="","",#REF!) -> #REF! | D19: =IF(#REF!="",G19,#REF!) -> #REF! | E19: =IF(#REF!="",F19,"") -> #REF! | F19: =IF(#REF!="","",#REF!) -> #REF! | G19: =IF(#REF!="","",#REF!) -> #REF! | H19: =IF(#REF!="","",#REF!) -> #REF! | I19: =IF(#REF!="","",#REF!) -> #REF! | J19: =IF(#REF!="","",#REF!) -> #REF! | K19: =IF(#REF!="","",#REF!) -> #REF! | L19: =IF(#REF!="","",#REF!) -> #REF! | M19: =IF(#REF!="","",#REF!) -> #REF! | ... P19: =IF(#REF!="","",#REF!) -> #REF!
A20: 12 | B20: =IF(#REF!="","",#REF!) -> #REF! | C20: =IF(#REF!="","",#REF!) -> #REF! | D20: =IF(#REF!="",G20,#REF!) -> #REF! | E20: =IF(#REF!="",F20,"") -> #REF! | F20: =IF(#REF!="","",#REF!) -> #REF! | G20: =IF(#REF!="","",#REF!) -> #REF! | H20: =IF(#REF!="","",#REF!) -> #REF! | I20: =IF(#REF!="","",#REF!) -> #REF! | J20: =IF(#REF!="","",#REF!) -> #REF! | K20: =IF(#REF!="","",#REF!) -> #REF! | L20: =IF(#REF!="","",#REF!) -> #REF! | M20: =IF(#REF!="","",#REF!) -> #REF! | ... P20: =IF(#REF!="","",#REF!) -> #REF!
... A36: 28 | B36: =IF(#REF!="","",#REF!) -> #REF! | C36: =IF(#REF!="","",#REF!) -> #REF! | D36: =IF(#REF!="",G36,#REF!) -> #REF! | E36: =IF(#REF!="",F36,"") -> #REF! | F36: =IF(#REF!="","",#REF!) -> #REF! | G36: =IF(#REF!="","",#REF!) -> #REF! | H36: =IF(#REF!="","",#REF!) -> #REF! | I36: =IF(#REF!="","",#REF!) -> #REF! | J36: =IF(#REF!="","",#REF!) -> #REF! | K36: =IF(#REF!="","",#REF!) -> #REF! | L36: =IF(#REF!="","",#REF!) -> #REF! | M36: =IF(#REF!="","",#REF!) -> #REF! | ... P36: =IF(#REF!="","",#REF!) -> #REF!
B37: 日付及び船長又は委任を受けた代理人若しくは船舶の職員による署名
B38: Date and signature by master, authorizedagent or officer
O39: (注） ※の付されている項目については記入不要。
B40: =#REF! -> #REF! | E40: 船長 宮野 修司 | O40: Note It is not necessary to fill in the item marked"※"
B41: =#REF! -> #REF!

Sheet Guideline
C1: Guideline for "Crew Roll for Certificate"
C3: ☆ Certificates and license with validity to be high-lighted automatically programmed based on following conditions.
C4: - Employment agreement (SEA)/Medical check : 31 days to expire = Yellow, then after expired = Red
C5: - Other than SEA, and Medical check : 6 month to expire = Yellow, then after expired = Red
C6: ☆☆ For the double checking purpose, master is requested to inform to manning company, and
C7: NSU Seamen team, if find out Yellow & Red high-lighted license or certificates.
C9: <Liberia Flag>
C10: Form "1" Certification of Home country
B11: Subject | D11: Remark
B12: 1-1. Rank
C13: Input the rank of crew.
B15: 1-2. & 1-3. Name
C16: Input the name of crew.
B18: 1-4. Nationality
C19: Input the nationality of crew.
B21: 1-5. Passport | D21: All Crew & Cadet
C22: Input Certificate No. & expiry date of the passport.
B25: 1-6. COC (Certificate of competency) | D25: Deck officer & Engineer
C26: Input Certificate No. & expiry date of home country COC.
B28: 1-7. Seamen's Book | D28: All Crew & Cadet
C29: Input Seamen's book No. & expiry date of home country.
B31: 1-8. GMDSS
C32: Input GMDSS certificate No. & expiry date of home country. | D32: Deck Officer
B34: 1-9. Security (SSO / SDSD) | D34: SSO - Master and/or C/O
C35: Input security certificate No. & expiry date (SSO or SDSD) of home country. | D35: SDSD - all crew except the person
C36: SSO - Ship Security Officer | D36: who has SSO cert.
C37: SDSD - Seafarers with Designated Security Duties. | D37: *At least, one SSO holder must
D38: be on board the vessel
B40: 1-10. Watch Keeping / Ship's Cook | D40: Watch Keeping - Deck and Eng. Rating
C41: Input Yes, if crew has endorsement of watch keeping of home country. | D41: (this is only applicable for crew
D42: who has watch keeping)
B44: 1-11. Yellow Fever | D44: All Crew
C45: Input Expiry date of Yellow Fever. | D45: (even have validity on the cert,
C46: If validity is stated as lifetime(life of person vaccinated) ➡ put N/A | D46: the cert is good thru life time)
B49: 1-12. Medical check | D49: All Crew
C50: Input Expiry date of medical check.
C51: (Company rule - The Expiry date is 1 year from last medical check. Ref: SMC-1601)
C52: Please arrange medical check for crew in appropriate timing, whose medical check will expire in near future.
B57: 1
C58: Guideline for "Crew Roll for Certificate"
...

Sheet Home country (Form 1 & Form 2)
B2: Crew Roll for Certificate | J2: Home Coutry | R2: "Form 1"
D4: Name of vessel : | E4: NSU TRUST | G4: Registry : | H4: LIBERIA | Q4: Date : | R4: 45936
C6: 1 - 1 | D6: 1 - 2 | E6: 1 - 3 | F6: 1 -4 | G6: 1 - 5 | I6: 1 - 6 | K6: 1 - 7 | M6: 1 - 8 | O6: 1 - 9 | Q6: 1 - 10 | R6: 1 - 11 | S6: 1 - 12
C7: RANK | D7: NAME | G7: PASSPORT | I7: COC | K7: Seamen's Book | M7: GMDSS | O7: Security | Q7: Watch | R7: Yellow | S7: Medical
D8: FAMILY | E8: GIVEN | F8: NATIONALITY | O8: (SSO / SDSD) | Q8: Keeping | R8: Fever | S8: Check
G9: Cert. No. | H9: Expire | I9: Cert. No. | J9: Expire | K9: Cert. No. | L9: Expire | M9: Cert. No. | N9: Expire | O9: Cert. No. | P9: Expire | Q9: Ship's Cook
H10: YYYY/MM/DD | J10: YYYY/MM/DD | L10: YYYY/MM/DD | N10: YYYY/MM/DD | P10: YYYY/MM/DD | R10: EXP Date | S10: EXP Date
B11: 1 | C11: MASTER | D11: NGUYEN | E11: THANH VIET | F11: VIETNAMESE | G11: C9505805 | H11: 47881 | I11: G2444.MT1-02 | J11: 47143 | K11: HPG-09463 | L11: UNLIMITED | M11: A15001/HP.G-02 | N11: 47094 | O11: 2832.SO/BNHP | P11: 46716 | R11: N/A | S11: 46109
B12: 2 | C12: C/O | D12: NGUYEN | E12: HUY TUNG | F12: VIETNAMESE | G12: C5773536 | H12: 46974 | I12: G2008.CO1-02 | J12: 47170 | K12: HPG-20806 | L12: UNLIMITED | M12: A17475/HP.G-02 | N12: 47569 | O12: 2608.SO/BNHP | P12: 46616 | R12: N/A | S12: 46269
B13: 3 | C13: 2/O | D13: NGUYEN | E13: HAI TRUONG | F13: VIETNAMESE | G13: C9330514 | H13: 47754 | I13: A8545.DO1 | J13: 46623 | K13: VN019157-01 | L13: UNLIMITED | M13: A12689/HP.G | N13: 46593 | O13: 2501.SO/BNHP | P13: 46568 | R13: N/A | S13: 46028
B14: 4 | C14: 3/O | D14: TRAN | E14: VIET TOAN | F14: VIETNAMESE | G14: K0218815 | H14: 48298 | I14: A9514.DO1-01 | J14: 47240 | K14: VN026642-01 | L14: UNLIMITED | M14: A15731/HP.G-01 | N14: 47240 | O14: N014378/SSO-VMUC | P14: 46643 | R14: N/A | S14: 46171
B15: 5 | C15: C/E | D15: NGUYEN | E15: THANH TRUNG | F15: VIETNAMESE | G15: C9515494 | H15: 47860 | I15: G0261.CE1-03 | J15: 47576 | K15: HPG-08485 | L15: UNLIMITED | O15: C1598.SD/BNHP | P15: 46799 | R15: N/A | S15: 46203
B16: 6 | C16: 2/E | D16: DOAN | E16: VAN CUONG | F16: VIETNAMESE | G16: P00369304 | H16: 48434 | I16: A3367.SE1 | J16: 46624 | K16: HPG-36439-01 | L16: UNLIMITED | O16: C1593.SD/BNHP | P16: 46799 | R16: N/A | S16: 46028
B17: 7 | C17: 3/E | D17: NGUYEN | E17: THE DAT | F17: VIETNAMESE | G17: C2973980 | H17: 46482 | I17: A4152.SE1-01 | J17: 47455 | K17: VN009721-01 | L17: UNLIMITED | O17: B9824.SD/BNHP | P17: 46616 | R17: N/A | S17: 46028
B18: 8 | C18: 4/E | D18: DO | E18: ANH MINH | F18: VIETNAMESE | G18: P01107893 | H18: 48578 | I18: A9074.EO1-01 | J18: 47517 | K18: VN031498-02 | L18: UNLIMITED | O18: C4700.SD/BNHP | P18: 46952 | R18: N/A | S18: 46171
B19: 9 | C19: BSN | D19: LE | E19: VAN LINH | F19: VIETNAMESE | G19: C4154378 | H19: 46707 | K19: HPG-09475 | L19: UNLIMITED | O19: C722.SD/BNHP | P19: 46743 | Q19: YES | R19: N/A | S19: 46109
B20: 10 | C20: A/B | D20: NGUYEN | E20: QUANG THUY | F20: VIETNAMESE | G20: C5871271 | H20: 46986 | K20: HPG-18832 | L20: UNLIMITED | O20: D028705/SSD-VMUC | P20: 46869 | Q20: YES | R20: N/A | S20: 46112
B21: 11 | C21: A/B | D21: NGUYEN | E21: VAN CUONG | F21: VIETNAMESE | G21: C6770849 | H21: 47170 | K21: HPG-18258 | L21: UNLIMITED | O21: D3812.SD/BNHP | P21: 47534 | Q21: YES | R21: N/A | S21: 46171
B22: 12 | C22: A/B | D22: NGUYEN | E22: VAN BINH | F22: VIETNAMESE | G22: C9632893 | H22: 47957 | K22: VN018419-01 | L22: UNLIMITED | O22: D4393.SD/BNHP | P22: 47567 | Q22: YES | R22: N/A | S22: 46114
B23: 13 | C23: O/S | D23: NGUYEN | E23: VAN MONG | F23: VIETNAMESE | G23: K0309244 | H23: 48323 | K23: VN033054-01 | L23: UNLIMITED | O23: 2616/SSD-DH | P23: 46402 | Q23: YES | R23: N/A | S23: 46203
B24: 14 | C24: O/S | D24: HOANG | E24: TRONG HAN | F24: VIETNAMESE | G24: C9946036 | H24: 48346 | K24: HPG-16253 | L24: UNLIMITED | O24: C1371.SD/BNHP | P24: 46792 | Q24: YES | R24: N/A | S24: 46109
B25: 15 | C25: D/B | D25: TRAN | E25: QUANG HA | F25: VIETNAMESE | G25: P03612328 | H25: 49133 | K25: VN047121-01 | L25: UNLIMITED | O25: 5986/SSD-CD1 | P25: 47220 | R25: N/A | S25: 46171
B26: 16 | C26: #1OLR | D26: CAO | E26: DANG TUYEN | F26: VIETNAMESE | G26: E00298750 | H26: 48730 | K26: VN011737-01 | L26: UNLIMITED | O26: C5004.SD/BNHP | P26: 46967 | Q26: YES | R26: N/A | S26: 46028
B27: 17 | C27: OLR | D27: PHAN | E27: VAN DUC | F27: VIETNAMESE | G27: P02657056 | H27: 48833 | K27: VN011954-01 | L27: UNLIMITED | O27: C5770.SD/BNHP | P27: 47004 | Q27: YES | R27: N/A | S27: 46109
B28: 18 | C28: OLR | D28: TO | E28: TRUNG HIEU | F28: VIETNAMESE | G28: E02913777 | H28: 49323 | K28: VN034900-01 | L28: UNLIMITED | O28: B6704.SD/BNHP | P28: 46454 | Q28: YES | R28: N/A | S28: 46171
B29: 19 | C29: WPR | D29: BUI | E29: TUAN ANH | F29: VIETNAMESE | G29: C9332722 | H29: 47743 | K29: VN020324-01 | L29: UNLIMITED | O29: R240134/SSD.VMUC | P29: 47475 | R29: N/A | S29: 46114
B30: 20 | C30: C/CK | D30: NGUYEN | E30: DUY HIEU | F30: VIETNAMESE | G30: C2250064 | H30: 46272 | K30: VN003915-01 | L30: UNLIMITED | O30: D4396.SD/BNHP | P30: 47567 | Q30: YES | R30: 46434 | S30: 46109
B31: 21 | C31: M/M | D31: TRAN | E31: VAN HOAN | F31: VIETNAMESE | G31: C9971021 | H31: 48238 | K31: VN003940-01 | L31: UNLIMITED | O31: C9802.SD/BNHP | P31: 47224 | Q31: YES | R31: N/A | S31: 46171
B32: 22 | C32: D/CDT | D32: VU | E32: THUY ANH | F32: VIETNAMESE | G32: P03526693 | H32: 49088 | K32: VN045145-02 | L32: UNLIMITED | R32: N/A | S32: 46029
B33: 23 | C33: E/CDT | D33: NGUYEN | E33: CONG HUNG | F33: VIETNAMESE | G33: P03572645 | H33: 49092 | K33: VN041785-01 | L33: UNLIMITED | O33: D1093.SD/BNHP | P33: 47311 | R33: N/A | S33: 46029
B34: 24 | C34: E/CDT | D34: NGUYEN | E34: TUAN DAT | F34: VIETNAMESE | G34: E03867126 | H34: 49557 | K34: VN046244-02 | L34: UNLIMITED | O34: D4076.SD/BNHP | P34: 47549 | R34: N/A | S34: 46269
B35: 25 | C35: E/CDT | D35: NGUYEN | E35: TRONG DUC | F35: VIETNAMESE | G35: E04171136 | H35: 49561 | K35: VN046249-02 | L35: UNLIMITED | O35: D4075.SD/BNHP | P35: 47549 | R35: N/A | S35: 46269
B36: 26
B37: 27
B38: 28
B39: 29
Q41: Prepared by Master
B43: Crew Roll for Certificate | J43: Home Coutry | S43: "Form 2"
D45: Name of vessel : | E45: =E4 -> NSU TRUST | G45: Registry : | H45: LIBERIA | Q45: Date : | R45: =R4 -> 45936
C47: 2 - 1 | D47: 2 - 2 | E47: 2 - 3 | F47: 2 - 4 | G47: 2 - 5 | J47: 2 - 6 | L47: 2 - 7 | N47: 2 - 8 | P47: 2 - 9 | R47: 2 - 10 | S47: 2 - 11
...

Sheet Flag state (Form 3)
B2: Crew Roll for Certificate | J2: Flag state | R2: "Form 3"
D4: Name of vessel : | E4: ='Home country (Form 1 & Form 2)'!E4 -> NSU TRUST | G4: Registry : | H4: ='Home country (Form 1 & Form 2)'!H45:I45 -> LIBERIA | P4: Date : | Q4: ='Home country (Form 1 & Form 2)'!R4 -> 45936
C6: 3 - 1 | D6: 3 - 2 | E6: 3 - 3 | F6: 3 - 4 | G6: 3 - 5 | I6: 3 - 6 | K6: 3 - 7 | M6: 3 - 8 | O6: 3 - 9 | Q6: 3-10
C7: RANK | D7: NAME | G7: COC | I7: Seamen's Book | K7: Watch Keeping (SQC) | M7: Cook(SQC) | O7: Security(SQC) | Q7: Basic Special
D8: FAMILY | E8: GIVEN | F8: NATIONALITY | O8: (SSO / SDSD) | Q8: Certificate
G9: Cert. No. | H9: Expire | I9: Cert. No. | J9: Expire | L9: Expire | P9: Expire | Q9: (SQC)
H10: YYYY/MM/DD | J10: YYYY/MM/DD | L10: YYYY/MM/DD | P10: YYYY/MM/DD
B11: 1 | C11: =IF('Home country (Form 1 & Form 2)'!C53="","",'Home country (Form 1 & Form 2)'!C53) -> MASTER | D11: =IF('Home country (Form 1 & Form 2)'!D53="","",'Home country (Form 1 & Form 2)'!D53) -> NGUYEN | E11: =IF('Home country (Form 1 & Form 2)'!E53="","",'Home country (Form 1 & Form 2)'!E53) -> THANH VIET | F11: =IF('Home country (Form 1 & Form 2)'!F53="","",'Home country (Form 1 & Form 2)'!F53) -> VIETNAMESE | G11: 1456972 | H11: 47143 | I11: 2008673 | J11: 47589 | O11: SSO | P11: UNLIMITED | Q11: YES
B12: 2 | C12: =IF('Home country (Form 1 & Form 2)'!C54="","",'Home country (Form 1 & Form 2)'!C54) -> C/O | D12: =IF('Home country (Form 1 & Form 2)'!D54="","",'Home country (Form 1 & Form 2)'!D54) -> NGUYEN | E12: =IF('Home country (Form 1 & Form 2)'!E54="","",'Home country (Form 1 & Form 2)'!E54) -> HUY TUNG | F12: =IF('Home country (Form 1 & Form 2)'!F54="","",'Home country (Form 1 & Form 2)'!F54) -> VIETNAMESE | G12: 1389579 | H12: 47170 | I12: 1900535 | J12: 47224 | O12: SSO | P12: UNLIMITED | Q12: YES
B13: 3 | C13: =IF('Home country (Form 1 & Form 2)'!C55="","",'Home country (Form 1 & Form 2)'!C55) -> 2/O | D13: =IF('Home country (Form 1 & Form 2)'!D55="","",'Home country (Form 1 & Form 2)'!D55) -> NGUYEN | E13: =IF('Home country (Form 1 & Form 2)'!E55="","",'Home country (Form 1 & Form 2)'!E55) -> HAI TRUONG | F13: =IF('Home country (Form 1 & Form 2)'!F55="","",'Home country (Form 1 & Form 2)'!F55) -> VIETNAMESE | G13: 1298738 | H13: 46623 | I13: 1743247 | J13: 46684 | O13: SSO | P13: UNLIMITED | Q13: YES
B14: 4 | C14: =IF('Home country (Form 1 & Form 2)'!C56="","",'Home country (Form 1 & Form 2)'!C56) -> 3/O | D14: =IF('Home country (Form 1 & Form 2)'!D56="","",'Home country (Form 1 & Form 2)'!D56) -> TRAN | E14: =IF('Home country (Form 1 & Form 2)'!E56="","",'Home country (Form 1 & Form 2)'!E56) -> VIET TOAN | F14: =IF('Home country (Form 1 & Form 2)'!F56="","",'Home country (Form 1 & Form 2)'!F56) -> VIETNAMESE | G14: 1468761 | H14: 47240 | I14: 2028154 | J14: 47649 | O14: SSO | P14: UNLIMITED | Q14: YES
B15: 5 | C15: =IF('Home country (Form 1 & Form 2)'!C57="","",'Home country (Form 1 & Form 2)'!C57) -> C/E | D15: =IF('Home country (Form 1 & Form 2)'!D57="","",'Home country (Form 1 & Form 2)'!D57) -> NGUYEN | E15: =IF('Home country (Form 1 & Form 2)'!E57="","",'Home country (Form 1 & Form 2)'!E57) -> THANH TRUNG | F15: =IF('Home country (Form 1 & Form 2)'!F57="","",'Home country (Form 1 & Form 2)'!F57) -> VIETNAMESE | G15: 1479427 | H15: 47576 | I15: 1768480 | J15: 46804 | O15: SDSD | P15: 46799 | Q15: YES
B16: 6 | C16: =IF('Home country (Form 1 & Form 2)'!C58="","",'Home country (Form 1 & Form 2)'!C58) -> 2/E | D16: =IF('Home country (Form 1 & Form 2)'!D58="","",'Home country (Form 1 & Form 2)'!D58) -> DOAN | E16: =IF('Home country (Form 1 & Form 2)'!E58="","",'Home country (Form 1 & Form 2)'!E58) -> VAN CUONG | F16: =IF('Home country (Form 1 & Form 2)'!F58="","",'Home country (Form 1 & Form 2)'!F58) -> VIETNAMESE | G16: 1440131 | H16: 46624 | I16: 1977162 | J16: 47497 | O16: SDSD | P16: 46799 | Q16: YES
B17: 7 | C17: =IF('Home country (Form 1 & Form 2)'!C59="","",'Home country (Form 1 & Form 2)'!C59) -> 3/E | D17: =IF('Home country (Form 1 & Form 2)'!D59="","",'Home country (Form 1 & Form 2)'!D59) -> NGUYEN | E17: =IF('Home country (Form 1 & Form 2)'!E59="","",'Home country (Form 1 & Form 2)'!E59) -> THE DAT | F17: =IF('Home country (Form 1 & Form 2)'!F59="","",'Home country (Form 1 & Form 2)'!F59) -> VIETNAMESE | G17: 1440163 | H17: 47455 | I17: 1977163 | J17: 47497 | O17: SDSD | P17: 46616 | Q17: YES
B18: 8 | C18: =IF('Home country (Form 1 & Form 2)'!C60="","",'Home country (Form 1 & Form 2)'!C60) -> 4/E | D18: =IF('Home country (Form 1 & Form 2)'!D60="","",'Home country (Form 1 & Form 2)'!D60) -> DO | E18: =IF('Home country (Form 1 & Form 2)'!E60="","",'Home country (Form 1 & Form 2)'!E60) -> ANH MINH | F18: =IF('Home country (Form 1 & Form 2)'!F60="","",'Home country (Form 1 & Form 2)'!F60) -> VIETNAMESE | G18: 1468773 | H18: 47517 | I18: 2028155 | J18: 47647 | O18: SDSD | P18: 46952 | Q18: YES
B19: 9 | C19: =IF('Home country (Form 1 & Form 2)'!C61="","",'Home country (Form 1 & Form 2)'!C61) -> BSN | D19: =IF('Home country (Form 1 & Form 2)'!D61="","",'Home country (Form 1 & Form 2)'!D61) -> LE | E19: =IF('Home country (Form 1 & Form 2)'!E61="","",'Home country (Form 1 & Form 2)'!E61) -> VAN LINH | F19: =IF('Home country (Form 1 & Form 2)'!F61="","",'Home country (Form 1 & Form 2)'!F61) -> VIETNAMESE | I19: 2008674 | J19: 47589 | K19: YES | L19: 46250 | O19: SDSD | P19: 46743 | Q19: YES
B20: 10 | C20: =IF('Home country (Form 1 & Form 2)'!C62="","",'Home country (Form 1 & Form 2)'!C62) -> A/B | D20: =IF('Home country (Form 1 & Form 2)'!D62="","",'Home country (Form 1 & Form 2)'!D62) -> NGUYEN | E20: =IF('Home country (Form 1 & Form 2)'!E62="","",'Home country (Form 1 & Form 2)'!E62) -> QUANG THUY | F20: =IF('Home country (Form 1 & Form 2)'!F62="","",'Home country (Form 1 & Form 2)'!F62) -> VIETNAMESE | I20: 2008675 | J20: 47589 | K20: YES | L20: 46385 | O20: SDSD | P20: 46869 | Q20: YES
B21: 11 | C21: =IF('Home country (Form 1 & Form 2)'!C63="","",'Home country (Form 1 & Form 2)'!C63) -> A/B | D21: =IF('Home country (Form 1 & Form 2)'!D63="","",'Home country (Form 1 & Form 2)'!D63) -> NGUYEN | E21: =IF('Home country (Form 1 & Form 2)'!E63="","",'Home country (Form 1 & Form 2)'!E63) -> VAN CUONG | F21: =IF('Home country (Form 1 & Form 2)'!F63="","",'Home country (Form 1 & Form 2)'!F63) -> VIETNAMESE | I21: 1655969 | J21: 46390 | K21: YES | L21: 47540 | O21: SDSD | P21: 47534 | Q21: YES
B22: 12 | C22: =IF('Home country (Form 1 & Form 2)'!C64="","",'Home country (Form 1 & Form 2)'!C64) -> A/B | D22: =IF('Home country (Form 1 & Form 2)'!D64="","",'Home country (Form 1 & Form 2)'!D64) -> NGUYEN | E22: =IF('Home country (Form 1 & Form 2)'!E64="","",'Home country (Form 1 & Form 2)'!E64) -> VAN BINH | F22: =IF('Home country (Form 1 & Form 2)'!F64="","",'Home country (Form 1 & Form 2)'!F64) -> VIETNAMESE | I22: 2008676 | J22: 47589 | K22: YES | L22: 46995 | O22: SDSD | P22: 47567 | Q22: YES
B23: 13 | C23: =IF('Home country (Form 1 & Form 2)'!C65="","",'Home country (Form 1 & Form 2)'!C65) -> O/S | D23: =IF('Home country (Form 1 & Form 2)'!D65="","",'Home country (Form 1 & Form 2)'!D65) -> NGUYEN | E23: =IF('Home country (Form 1 & Form 2)'!E65="","",'Home country (Form 1 & Form 2)'!E65) -> VAN MONG | F23: =IF('Home country (Form 1 & Form 2)'!F65="","",'Home country (Form 1 & Form 2)'!F65) -> VIETNAMESE | I23: 2050273 | J23: 47696 | K23: YES | L23: 47092 | O23: SDSD | P23: 46402 | Q23: YES
B24: 14 | C24: =IF('Home country (Form 1 & Form 2)'!C66="","",'Home country (Form 1 & Form 2)'!C66) -> O/S | D24: =IF('Home country (Form 1 & Form 2)'!D66="","",'Home country (Form 1 & Form 2)'!D66) -> HOANG | E24: =IF('Home country (Form 1 & Form 2)'!E66="","",'Home country (Form 1 & Form 2)'!E66) -> TRONG HAN | F24: =IF('Home country (Form 1 & Form 2)'!F66="","",'Home country (Form 1 & Form 2)'!F66) -> VIETNAMESE | I24: 2008677 | J24: 47589 | K24: YES | L24: 46920 | O24: SDSD | P24: 46792 | Q24: YES
B25: 15 | C25: =IF('Home country (Form 1 & Form 2)'!C67="","",'Home country (Form 1 & Form 2)'!C67) -> D/B | D25: =IF('Home country (Form 1 & Form 2)'!D67="","",'Home country (Form 1 & Form 2)'!D67) -> TRAN | E25: =IF('Home country (Form 1 & Form 2)'!E67="","",'Home country (Form 1 & Form 2)'!E67) -> QUANG HA | F25: =IF('Home country (Form 1 & Form 2)'!F67="","",'Home country (Form 1 & Form 2)'!F67) -> VIETNAMESE | I25: 2028156 | J25: 47647 | O25: SDSD | P25: 47220 | Q25: YES
B26: 16 | C26: =IF('Home country (Form 1 & Form 2)'!C68="","",'Home country (Form 1 & Form 2)'!C68) -> #1OLR | D26: =IF('Home country (Form 1 & Form 2)'!D68="","",'Home country (Form 1 & Form 2)'!D68) -> CAO | E26: =IF('Home country (Form 1 & Form 2)'!E68="","",'Home country (Form 1 & Form 2)'!E68) -> DANG TUYEN | F26: =IF('Home country (Form 1 & Form 2)'!F68="","",'Home country (Form 1 & Form 2)'!F68) -> VIETNAMESE | I26: 1977164 | J26: 47497 | K26: YES | L26: 47377 | O26: SDSD | P26: 46967 | Q26: YES
B27: 17 | C27: =IF('Home country (Form 1 & Form 2)'!C69="","",'Home country (Form 1 & Form 2)'!C69) -> OLR | D27: =IF('Home country (Form 1 & Form 2)'!D69="","",'Home country (Form 1 & Form 2)'!D69) -> PHAN | E27: =IF('Home country (Form 1 & Form 2)'!E69="","",'Home country (Form 1 & Form 2)'!E69) -> VAN DUC | F27: =IF('Home country (Form 1 & Form 2)'!F69="","",'Home country (Form 1 & Form 2)'!F69) -> VIETNAMESE | I27: 1723090 | J27: 46623 | K27: YES | L27: 47426 | O27: SDSD | P27: 47004 | Q27: YES
B28: 18 | C28: =IF('Home country (Form 1 & Form 2)'!C70="","",'Home country (Form 1 & Form 2)'!C70) -> OLR | D28: =IF('Home country (Form 1 & Form 2)'!D70="","",'Home country (Form 1 & Form 2)'!D70) -> TO | E28: =IF('Home country (Form 1 & Form 2)'!E70="","",'Home country (Form 1 & Form 2)'!E70) -> TRUNG HIEU | F28: =IF('Home country (Form 1 & Form 2)'!F70="","",'Home country (Form 1 & Form 2)'!F70) -> VIETNAMESE | I28: 1892848 | J28: 47202 | K28: YES | L28: 46692 | O28: SDSD | P28: 46454 | Q28: YES
B29: 19 | C29: =IF('Home country (Form 1 & Form 2)'!C71="","",'Home country (Form 1 & Form 2)'!C71) -> WPR | D29: =IF('Home country (Form 1 & Form 2)'!D71="","",'Home country (Form 1 & Form 2)'!D71) -> BUI | E29: =IF('Home country (Form 1 & Form 2)'!E71="","",'Home country (Form 1 & Form 2)'!E71) -> TUAN ANH | F29: =IF('Home country (Form 1 & Form 2)'!F71="","",'Home country (Form 1 & Form 2)'!F71) -> VIETNAMESE | I29: 2008678 | J29: 47589 | O29: SDSD | P29: 47475 | Q29: YES
B30: 20 | C30: =IF('Home country (Form 1 & Form 2)'!C72="","",'Home country (Form 1 & Form 2)'!C72) -> C/CK | D30: =IF('Home country (Form 1 & Form 2)'!D72="","",'Home country (Form 1 & Form 2)'!D72) -> NGUYEN | E30: =IF('Home country (Form 1 & Form 2)'!E72="","",'Home country (Form 1 & Form 2)'!E72) -> DUY HIEU | F30: =IF('Home country (Form 1 & Form 2)'!F72="","",'Home country (Form 1 & Form 2)'!F72) -> VIETNAMESE | I30: 2008679 | J30: 47589 | M30: YES | O30: SDSD | P30: 47567 | Q30: YES
B31: 21 | C31: =IF('Home country (Form 1 & Form 2)'!C73="","",'Home country (Form 1 & Form 2)'!C73) -> M/M | D31: =IF('Home country (Form 1 & Form 2)'!D73="","",'Home country (Form 1 & Form 2)'!D73) -> TRAN | E31: =IF('Home country (Form 1 & Form 2)'!E73="","",'Home country (Form 1 & Form 2)'!E73) -> VAN HOAN | F31: =IF('Home country (Form 1 & Form 2)'!F73="","",'Home country (Form 1 & Form 2)'!F73) -> VIETNAMESE | I31: 2028157 | J31: 47647 | M31: YES | O31: SDSD | P31: 47224 | Q31: YES
B32: 22 | C32: =IF('Home country (Form 1 & Form 2)'!C74="","",'Home country (Form 1 & Form 2)'!C74) -> D/CDT | D32: =IF('Home country (Form 1 & Form 2)'!D74="","",'Home country (Form 1 & Form 2)'!D74) -> VU | E32: =IF('Home country (Form 1 & Form 2)'!E74="","",'Home country (Form 1 & Form 2)'!E74) -> THUY ANH | F32: VIETNAMESE | I32: 1977165 | J32: 47497 | O32: SAS | P32: 47267 | Q32: YES
B33: 23 | C33: =IF('Home country (Form 1 & Form 2)'!C75="","",'Home country (Form 1 & Form 2)'!C75) -> E/CDT | D33: =IF('Home country (Form 1 & Form 2)'!D75="","",'Home country (Form 1 & Form 2)'!D75) -> NGUYEN | E33: =IF('Home country (Form 1 & Form 2)'!E75="","",'Home country (Form 1 & Form 2)'!E75) -> CONG HUNG | F33: =IF('Home country (Form 1 & Form 2)'!F75="","",'Home country (Form 1 & Form 2)'!F75) -> VIETNAMESE | I33: 1977166 | J33: 47497 | O33: SDSD | P33: 47311 | Q33: YES
B34: 24 | C34: =IF('Home country (Form 1 & Form 2)'!C76="","",'Home country (Form 1 & Form 2)'!C76) -> E/CDT | D34: =IF('Home country (Form 1 & Form 2)'!D76="","",'Home country (Form 1 & Form 2)'!D76) -> NGUYEN | E34: =IF('Home country (Form 1 & Form 2)'!E76="","",'Home country (Form 1 & Form 2)'!E76) -> TUAN DAT | F34: =IF('Home country (Form 1 & Form 2)'!F76="","",'Home country (Form 1 & Form 2)'!F76) -> VIETNAMESE | I34: 2057276 | J34: 47749 | O34: SDSD | P34: 47549 | Q34: YES
B35: 25 | C35: =IF('Home country (Form 1 & Form 2)'!C77="","",'Home country (Form 1 & Form 2)'!C77) -> E/CDT | D35: =IF('Home country (Form 1 & Form 2)'!D77="","",'Home country (Form 1 & Form 2)'!D77) -> NGUYEN | E35: =IF('Home country (Form 1 & Form 2)'!E77="","",'Home country (Form 1 & Form 2)'!E77) -> TRONG DUC | F35: =IF('Home country (Form 1 & Form 2)'!F77="","",'Home country (Form 1 & Form 2)'!F77) -> VIETNAMESE | I35: 2057277 | J35: 47749 | O35: SDSD | P35: 47549 | Q35: YES
B36: 26 | C36: =IF('Home country (Form 1 & Form 2)'!C78="","",'Home country (Form 1 & Form 2)'!C78) | D36: =IF('Home country (Form 1 & Form 2)'!D78="","",'Home country (Form 1 & Form 2)'!D78) | E36: =IF('Home country (Form 1 & Form 2)'!E78="","",'Home country (Form 1 & Form 2)'!E78) | F36: =IF('Home country (Form 1 & Form 2)'!F78="","",'Home country (Form 1 & Form 2)'!F78)
B37: 27 | C37: =IF('Home country (Form 1 & Form 2)'!C79="","",'Home country (Form 1 & Form 2)'!C79) | D37: =IF('Home country (Form 1 & Form 2)'!D79="","",'Home country (Form 1 & Form 2)'!D79) | E37: =IF('Home country (Form 1 & Form 2)'!E79="","",'Home country (Form 1 & Form 2)'!E79) | F37: =IF('Home country (Form 1 & Form 2)'!F79="","",'Home country (Form 1 & Form 2)'!F79)
B38: 28 | C38: =IF('Home country (Form 1 & Form 2)'!C80="","",'Home country (Form 1 & Form 2)'!C80) | D38: =IF('Home country (Form 1 & Form 2)'!D80="","",'Home country (Form 1 & Form 2)'!D80) | E38: =IF('Home country (Form 1 & Form 2)'!E80="","",'Home country (Form 1 & Form 2)'!E80) | F38: =IF('Home country (Form 1 & Form 2)'!F80="","",'Home country (Form 1 & Form 2)'!F80)
B39: 29 | C39: =IF('Home country (Form 1 & Form 2)'!C81="","",'Home country (Form 1 & Form 2)'!C81) | D39: =IF('Home country (Form 1 & Form 2)'!D81="","",'Home country (Form 1 & Form 2)'!D81) | E39: =IF('Home country (Form 1 & Form 2)'!E81="","",'Home country (Form 1 & Form 2)'!E81) | F39: =IF('Home country (Form 1 & Form 2)'!F81="","",'Home country (Form 1 & Form 2)'!F81)
O41: Prepared by Master
